2023-08-18 14:34:16,464 - APIproject2 - ERROR - Exception on /calculate_pv [POST]
Traceback (most recent call last):
  File "/home/meshuggah/.local/lib/python3.10/site-packages/flask/app.py", line 2190, in wsgi_app
    response = self.full_dispatch_request()
  File "/home/meshuggah/.local/lib/python3.10/site-packages/flask/app.py", line 1486, in full_dispatch_request
    rv = self.handle_user_exception(e)
  File "/home/meshuggah/.local/lib/python3.10/site-packages/flask/app.py", line 1484, in full_dispatch_request
    rv = self.dispatch_request()
  File "/home/meshuggah/.local/lib/python3.10/site-packages/flask/app.py", line 1469, in dispatch_request
    return self.ensure_sync(self.view_functions[rule.endpoint])(**view_args)
  File "/home/meshuggah/heavy/enervivo/APIproject/TADD_API/APIproject2.py", line 172, in calculate_pv
    configuration = Configuration(**configuration_data)
  File "pydantic/main.py", line 341, in pydantic.main.BaseModel.__init__
pydantic.error_wrappers.ValidationError: 1 validation error for Configuration
long
  field required (type=value_error.missing)
2023-08-18 17:34:58,378 - APIproject2 - ERROR - Exception on /calculate_pv [POST]
Traceback (most recent call last):
  File "/home/meshuggah/.local/lib/python3.10/site-packages/flask/app.py", line 2190, in wsgi_app
    response = self.full_dispatch_request()
  File "/home/meshuggah/.local/lib/python3.10/site-packages/flask/app.py", line 1486, in full_dispatch_request
    rv = self.handle_user_exception(e)
  File "/home/meshuggah/.local/lib/python3.10/site-packages/flask/app.py", line 1484, in full_dispatch_request
    rv = self.dispatch_request()
  File "/home/meshuggah/.local/lib/python3.10/site-packages/flask/app.py", line 1469, in dispatch_request
    return self.ensure_sync(self.view_functions[rule.endpoint])(**view_args)
  File "/home/meshuggah/heavy/enervivo/APIproject/TADD_API/APIproject2.py", line 472, in calculate_pv
    return jsonify(data)
  File "/home/meshuggah/.local/lib/python3.10/site-packages/flask/json/__init__.py", line 170, in jsonify
    return current_app.json.response(*args, **kwargs)
  File "/home/meshuggah/.local/lib/python3.10/site-packages/flask/json/provider.py", line 215, in response
    f"{self.dumps(obj, **dump_args)}\n", mimetype=self.mimetype
  File "/home/meshuggah/.local/lib/python3.10/site-packages/flask/json/provider.py", line 180, in dumps
    return json.dumps(obj, **kwargs)
  File "/usr/lib/python3.10/json/__init__.py", line 238, in dumps
    **kw).encode(obj)
  File "/usr/lib/python3.10/json/encoder.py", line 199, in encode
    chunks = self.iterencode(o, _one_shot=True)
  File "/usr/lib/python3.10/json/encoder.py", line 257, in iterencode
    return _iterencode(o, 0)
  File "/home/meshuggah/.local/lib/python3.10/site-packages/flask/json/provider.py", line 120, in _default
    raise TypeError(f"Object of type {type(o).__name__} is not JSON serializable")
TypeError: Object of type Series is not JSON serializable
2023-08-18 17:48:45,760 - APIproject2 - ERROR - Exception on /calculate_pv [POST]
Traceback (most recent call last):
  File "/home/meshuggah/.local/lib/python3.10/site-packages/flask/app.py", line 2190, in wsgi_app
    response = self.full_dispatch_request()
  File "/home/meshuggah/.local/lib/python3.10/site-packages/flask/app.py", line 1486, in full_dispatch_request
    rv = self.handle_user_exception(e)
  File "/home/meshuggah/.local/lib/python3.10/site-packages/flask/app.py", line 1484, in full_dispatch_request
    rv = self.dispatch_request()
  File "/home/meshuggah/.local/lib/python3.10/site-packages/flask/app.py", line 1469, in dispatch_request
    return self.ensure_sync(self.view_functions[rule.endpoint])(**view_args)
  File "/home/meshuggah/heavy/enervivo/APIproject/TADD_API/APIproject2.py", line 456, in calculate_pv
    result = n_h90_for_config.to_dict()
AttributeError: 'dict' object has no attribute 'to_dict'
2023-08-18 17:49:26,744 - APIproject2 - ERROR - Exception on /calculate_pv [POST]
Traceback (most recent call last):
  File "/home/meshuggah/.local/lib/python3.10/site-packages/flask/app.py", line 2190, in wsgi_app
    response = self.full_dispatch_request()
  File "/home/meshuggah/.local/lib/python3.10/site-packages/flask/app.py", line 1486, in full_dispatch_request
    rv = self.handle_user_exception(e)
  File "/home/meshuggah/.local/lib/python3.10/site-packages/flask/app.py", line 1484, in full_dispatch_request
    rv = self.dispatch_request()
  File "/home/meshuggah/.local/lib/python3.10/site-packages/flask/app.py", line 1469, in dispatch_request
    return self.ensure_sync(self.view_functions[rule.endpoint])(**view_args)
  File "/home/meshuggah/heavy/enervivo/APIproject/TADD_API/APIproject2.py", line 475, in calculate_pv
    return jsonify(data)
  File "/home/meshuggah/.local/lib/python3.10/site-packages/flask/json/__init__.py", line 170, in jsonify
    return current_app.json.response(*args, **kwargs)
  File "/home/meshuggah/.local/lib/python3.10/site-packages/flask/json/provider.py", line 215, in response
    f"{self.dumps(obj, **dump_args)}\n", mimetype=self.mimetype
  File "/home/meshuggah/.local/lib/python3.10/site-packages/flask/json/provider.py", line 180, in dumps
    return json.dumps(obj, **kwargs)
  File "/usr/lib/python3.10/json/__init__.py", line 238, in dumps
    **kw).encode(obj)
  File "/usr/lib/python3.10/json/encoder.py", line 199, in encode
    chunks = self.iterencode(o, _one_shot=True)
  File "/usr/lib/python3.10/json/encoder.py", line 257, in iterencode
    return _iterencode(o, 0)
  File "/home/meshuggah/.local/lib/python3.10/site-packages/flask/json/provider.py", line 120, in _default
    raise TypeError(f"Object of type {type(o).__name__} is not JSON serializable")
TypeError: Object of type Series is not JSON serializable
2023-08-18 17:51:02,958 - APIproject2 - ERROR - Exception on /calculate_pv [POST]
Traceback (most recent call last):
  File "/home/meshuggah/.local/lib/python3.10/site-packages/flask/app.py", line 2190, in wsgi_app
    response = self.full_dispatch_request()
  File "/home/meshuggah/.local/lib/python3.10/site-packages/flask/app.py", line 1486, in full_dispatch_request
    rv = self.handle_user_exception(e)
  File "/home/meshuggah/.local/lib/python3.10/site-packages/flask/app.py", line 1484, in full_dispatch_request
    rv = self.dispatch_request()
  File "/home/meshuggah/.local/lib/python3.10/site-packages/flask/app.py", line 1469, in dispatch_request
    return self.ensure_sync(self.view_functions[rule.endpoint])(**view_args)
  File "/home/meshuggah/heavy/enervivo/APIproject/TADD_API/APIproject2.py", line 475, in calculate_pv
    return jsonify(data)
  File "/home/meshuggah/.local/lib/python3.10/site-packages/flask/json/__init__.py", line 170, in jsonify
    return current_app.json.response(*args, **kwargs)
  File "/home/meshuggah/.local/lib/python3.10/site-packages/flask/json/provider.py", line 215, in response
    f"{self.dumps(obj, **dump_args)}\n", mimetype=self.mimetype
  File "/home/meshuggah/.local/lib/python3.10/site-packages/flask/json/provider.py", line 180, in dumps
    return json.dumps(obj, **kwargs)
  File "/usr/lib/python3.10/json/__init__.py", line 238, in dumps
    **kw).encode(obj)
  File "/usr/lib/python3.10/json/encoder.py", line 199, in encode
    chunks = self.iterencode(o, _one_shot=True)
  File "/usr/lib/python3.10/json/encoder.py", line 257, in iterencode
    return _iterencode(o, 0)
  File "/home/meshuggah/.local/lib/python3.10/site-packages/flask/json/provider.py", line 120, in _default
    raise TypeError(f"Object of type {type(o).__name__} is not JSON serializable")
TypeError: Object of type Series is not JSON serializable
2023-08-18 17:56:35,111 - APIproject2 - ERROR - Exception on /calculate_pv [POST]
Traceback (most recent call last):
  File "/home/meshuggah/.local/lib/python3.10/site-packages/flask/app.py", line 2190, in wsgi_app
    response = self.full_dispatch_request()
  File "/home/meshuggah/.local/lib/python3.10/site-packages/flask/app.py", line 1486, in full_dispatch_request
    rv = self.handle_user_exception(e)
  File "/home/meshuggah/.local/lib/python3.10/site-packages/flask/app.py", line 1484, in full_dispatch_request
    rv = self.dispatch_request()
  File "/home/meshuggah/.local/lib/python3.10/site-packages/flask/app.py", line 1469, in dispatch_request
    return self.ensure_sync(self.view_functions[rule.endpoint])(**view_args)
  File "/home/meshuggah/heavy/enervivo/APIproject/TADD_API/APIproject2.py", line 456, in calculate_pv
    result = n_h90_for_config.tolist()
AttributeError: 'dict' object has no attribute 'tolist'
2023-08-18 17:57:11,506 - APIproject2 - ERROR - Exception on /calculate_pv [POST]
Traceback (most recent call last):
  File "/home/meshuggah/.local/lib/python3.10/site-packages/flask/app.py", line 2190, in wsgi_app
    response = self.full_dispatch_request()
  File "/home/meshuggah/.local/lib/python3.10/site-packages/flask/app.py", line 1486, in full_dispatch_request
    rv = self.handle_user_exception(e)
  File "/home/meshuggah/.local/lib/python3.10/site-packages/flask/app.py", line 1484, in full_dispatch_request
    rv = self.dispatch_request()
  File "/home/meshuggah/.local/lib/python3.10/site-packages/flask/app.py", line 1469, in dispatch_request
    return self.ensure_sync(self.view_functions[rule.endpoint])(**view_args)
  File "/home/meshuggah/heavy/enervivo/APIproject/TADD_API/APIproject2.py", line 474, in calculate_pv
    data = {"result": result, gain: gains}
NameError: name 'gain' is not defined
2023-08-18 18:03:17,795 - APIproject2 - ERROR - Exception on /calculate_pv [POST]
Traceback (most recent call last):
  File "/home/meshuggah/.local/lib/python3.10/site-packages/flask/app.py", line 2190, in wsgi_app
    response = self.full_dispatch_request()
  File "/home/meshuggah/.local/lib/python3.10/site-packages/flask/app.py", line 1486, in full_dispatch_request
    rv = self.handle_user_exception(e)
  File "/home/meshuggah/.local/lib/python3.10/site-packages/flask/app.py", line 1484, in full_dispatch_request
    rv = self.dispatch_request()
  File "/home/meshuggah/.local/lib/python3.10/site-packages/flask/app.py", line 1469, in dispatch_request
    return self.ensure_sync(self.view_functions[rule.endpoint])(**view_args)
  File "/home/meshuggah/heavy/enervivo/APIproject/TADD_API/APIproject2.py", line 430, in calculate_pv
    n_h90_for_config = {config["name"]: round(sum(
  File "/home/meshuggah/heavy/enervivo/APIproject/TADD_API/APIproject2.py", line 431, in <dictcomp>
    P_ac_for_config[config["name"]]/1000/eta_module*configuration.r_P90))
TypeError: unsupported operand type(s) for /: 'dict' and 'int'
2023-08-18 18:09:44,323 - APIproject2 - ERROR - Exception on /calculate_pv [POST]
Traceback (most recent call last):
  File "/home/meshuggah/.local/lib/python3.10/site-packages/flask/app.py", line 2190, in wsgi_app
    response = self.full_dispatch_request()
  File "/home/meshuggah/.local/lib/python3.10/site-packages/flask/app.py", line 1486, in full_dispatch_request
    rv = self.handle_user_exception(e)
  File "/home/meshuggah/.local/lib/python3.10/site-packages/flask/app.py", line 1484, in full_dispatch_request
    rv = self.dispatch_request()
  File "/home/meshuggah/.local/lib/python3.10/site-packages/flask/app.py", line 1469, in dispatch_request
    return self.ensure_sync(self.view_functions[rule.endpoint])(**view_args)
  File "/home/meshuggah/heavy/enervivo/APIproject/TADD_API/APIproject2.py", line 432, in calculate_pv
    n_h90_for_config = {config["name"]: round(sum(
  File "/home/meshuggah/heavy/enervivo/APIproject/TADD_API/APIproject2.py", line 433, in <dictcomp>
    P_ac_for_config[config["name"]]/1000/eta_module*configuration.r_P90))
TypeError: unsupported operand type(s) for /: 'dict' and 'int'
2023-08-18 18:10:15,863 - APIproject2 - ERROR - Exception on /calculate_pv [POST]
Traceback (most recent call last):
  File "/home/meshuggah/.local/lib/python3.10/site-packages/flask/app.py", line 2190, in wsgi_app
    response = self.full_dispatch_request()
  File "/home/meshuggah/.local/lib/python3.10/site-packages/flask/app.py", line 1486, in full_dispatch_request
    rv = self.handle_user_exception(e)
  File "/home/meshuggah/.local/lib/python3.10/site-packages/flask/app.py", line 1484, in full_dispatch_request
    rv = self.dispatch_request()
  File "/home/meshuggah/.local/lib/python3.10/site-packages/flask/app.py", line 1469, in dispatch_request
    return self.ensure_sync(self.view_functions[rule.endpoint])(**view_args)
  File "/home/meshuggah/heavy/enervivo/APIproject/TADD_API/APIproject2.py", line 431, in calculate_pv
    n_h90_for_config = {config["name"]: round(sum(
  File "/home/meshuggah/heavy/enervivo/APIproject/TADD_API/APIproject2.py", line 432, in <dictcomp>
    P_ac_for_config[config["name"]]/1000/eta_module*configuration.r_P90))
TypeError: unsupported operand type(s) for /: 'dict' and 'int'
2023-08-18 18:11:15,756 - APIproject2 - ERROR - Exception on /calculate_pv [POST]
Traceback (most recent call last):
  File "/home/meshuggah/.local/lib/python3.10/site-packages/flask/app.py", line 2190, in wsgi_app
    response = self.full_dispatch_request()
  File "/home/meshuggah/.local/lib/python3.10/site-packages/flask/app.py", line 1486, in full_dispatch_request
    rv = self.handle_user_exception(e)
  File "/home/meshuggah/.local/lib/python3.10/site-packages/flask/app.py", line 1484, in full_dispatch_request
    rv = self.dispatch_request()
  File "/home/meshuggah/.local/lib/python3.10/site-packages/flask/app.py", line 1469, in dispatch_request
    return self.ensure_sync(self.view_functions[rule.endpoint])(**view_args)
  File "/home/meshuggah/heavy/enervivo/APIproject/TADD_API/APIproject2.py", line 480, in calculate_pv
    return jsonify(data)
  File "/home/meshuggah/.local/lib/python3.10/site-packages/flask/json/__init__.py", line 170, in jsonify
    return current_app.json.response(*args, **kwargs)
  File "/home/meshuggah/.local/lib/python3.10/site-packages/flask/json/provider.py", line 215, in response
    f"{self.dumps(obj, **dump_args)}\n", mimetype=self.mimetype
  File "/home/meshuggah/.local/lib/python3.10/site-packages/flask/json/provider.py", line 180, in dumps
    return json.dumps(obj, **kwargs)
  File "/usr/lib/python3.10/json/__init__.py", line 238, in dumps
    **kw).encode(obj)
  File "/usr/lib/python3.10/json/encoder.py", line 199, in encode
    chunks = self.iterencode(o, _one_shot=True)
  File "/usr/lib/python3.10/json/encoder.py", line 257, in iterencode
    return _iterencode(o, 0)
TypeError: keys must be str, int, float, bool or None, not Timestamp
2023-08-18 18:12:18,660 - APIproject2 - ERROR - Exception on /calculate_pv [POST]
Traceback (most recent call last):
  File "/home/meshuggah/.local/lib/python3.10/site-packages/flask/app.py", line 2190, in wsgi_app
    response = self.full_dispatch_request()
  File "/home/meshuggah/.local/lib/python3.10/site-packages/flask/app.py", line 1486, in full_dispatch_request
    rv = self.handle_user_exception(e)
  File "/home/meshuggah/.local/lib/python3.10/site-packages/flask/app.py", line 1484, in full_dispatch_request
    rv = self.dispatch_request()
  File "/home/meshuggah/.local/lib/python3.10/site-packages/flask/app.py", line 1469, in dispatch_request
    return self.ensure_sync(self.view_functions[rule.endpoint])(**view_args)
  File "/home/meshuggah/heavy/enervivo/APIproject/TADD_API/APIproject2.py", line 476, in calculate_pv
    P_ac_for_config = P_ac_for_config.tolist()
  File "/home/meshuggah/.local/lib/python3.10/site-packages/pandas/core/generic.py", line 5989, in __getattr__
    return object.__getattribute__(self, name)
AttributeError: 'DataFrame' object has no attribute 'tolist'
2023-08-18 18:13:00,606 - APIproject2 - ERROR - Exception on /calculate_pv [POST]
Traceback (most recent call last):
  File "/home/meshuggah/.local/lib/python3.10/site-packages/flask/app.py", line 2190, in wsgi_app
    response = self.full_dispatch_request()
  File "/home/meshuggah/.local/lib/python3.10/site-packages/flask/app.py", line 1486, in full_dispatch_request
    rv = self.handle_user_exception(e)
  File "/home/meshuggah/.local/lib/python3.10/site-packages/flask/app.py", line 1484, in full_dispatch_request
    rv = self.dispatch_request()
  File "/home/meshuggah/.local/lib/python3.10/site-packages/flask/app.py", line 1469, in dispatch_request
    return self.ensure_sync(self.view_functions[rule.endpoint])(**view_args)
  File "/home/meshuggah/heavy/enervivo/APIproject/TADD_API/APIproject2.py", line 477, in calculate_pv
    P_ac_for_config = P_ac_for_config.tolist()
AttributeError: 'dict' object has no attribute 'tolist'
2023-08-18 18:17:32,841 - APIproject2 - ERROR - Exception on /calculate_pv [POST]
Traceback (most recent call last):
  File "/home/meshuggah/.local/lib/python3.10/site-packages/flask/app.py", line 2190, in wsgi_app
    response = self.full_dispatch_request()
  File "/home/meshuggah/.local/lib/python3.10/site-packages/flask/app.py", line 1486, in full_dispatch_request
    rv = self.handle_user_exception(e)
  File "/home/meshuggah/.local/lib/python3.10/site-packages/flask/app.py", line 1484, in full_dispatch_request
    rv = self.dispatch_request()
  File "/home/meshuggah/.local/lib/python3.10/site-packages/flask/app.py", line 1469, in dispatch_request
    return self.ensure_sync(self.view_functions[rule.endpoint])(**view_args)
  File "/home/meshuggah/heavy/enervivo/APIproject/TADD_API/APIproject2.py", line 478, in calculate_pv
    P_ac_for_config = P_ac_for_config.tolist()
AttributeError: 'dict' object has no attribute 'tolist'
2023-08-18 18:47:58,668 - APIproject2 - ERROR - Exception on /calculate_pv [POST]
Traceback (most recent call last):
  File "/home/meshuggah/.local/lib/python3.10/site-packages/flask/app.py", line 2190, in wsgi_app
    response = self.full_dispatch_request()
  File "/home/meshuggah/.local/lib/python3.10/site-packages/flask/app.py", line 1486, in full_dispatch_request
    rv = self.handle_user_exception(e)
  File "/home/meshuggah/.local/lib/python3.10/site-packages/flask/app.py", line 1484, in full_dispatch_request
    rv = self.dispatch_request()
  File "/home/meshuggah/.local/lib/python3.10/site-packages/flask/app.py", line 1469, in dispatch_request
    return self.ensure_sync(self.view_functions[rule.endpoint])(**view_args)
  File "/home/meshuggah/heavy/enervivo/APIproject/TADD_API/APIproject2.py", line 469, in calculate_pv
    for col in P_ac_for_config.columns:
AttributeError: 'dict' object has no attribute 'columns'
2023-08-18 18:48:51,018 - APIproject2 - ERROR - Exception on /calculate_pv [POST]
Traceback (most recent call last):
  File "/home/meshuggah/.local/lib/python3.10/site-packages/flask/app.py", line 2190, in wsgi_app
    response = self.full_dispatch_request()
  File "/home/meshuggah/.local/lib/python3.10/site-packages/flask/app.py", line 1486, in full_dispatch_request
    rv = self.handle_user_exception(e)
  File "/home/meshuggah/.local/lib/python3.10/site-packages/flask/app.py", line 1484, in full_dispatch_request
    rv = self.dispatch_request()
  File "/home/meshuggah/.local/lib/python3.10/site-packages/flask/app.py", line 1469, in dispatch_request
    return self.ensure_sync(self.view_functions[rule.endpoint])(**view_args)
  File "/home/meshuggah/heavy/enervivo/APIproject/TADD_API/APIproject2.py", line 474, in calculate_pv
    return jsonify(data)
  File "/home/meshuggah/.local/lib/python3.10/site-packages/flask/json/__init__.py", line 170, in jsonify
    return current_app.json.response(*args, **kwargs)
  File "/home/meshuggah/.local/lib/python3.10/site-packages/flask/json/provider.py", line 215, in response
    f"{self.dumps(obj, **dump_args)}\n", mimetype=self.mimetype
  File "/home/meshuggah/.local/lib/python3.10/site-packages/flask/json/provider.py", line 180, in dumps
    return json.dumps(obj, **kwargs)
  File "/usr/lib/python3.10/json/__init__.py", line 238, in dumps
    **kw).encode(obj)
  File "/usr/lib/python3.10/json/encoder.py", line 199, in encode
    chunks = self.iterencode(o, _one_shot=True)
  File "/usr/lib/python3.10/json/encoder.py", line 257, in iterencode
    return _iterencode(o, 0)
TypeError: keys must be str, int, float, bool or None, not Timestamp
2023-08-18 19:08:15,305 - APIproject2 - ERROR - Exception on /calculate_pv [POST]
Traceback (most recent call last):
  File "C:\Users\pc\anaconda3\lib\site-packages\flask\app.py", line 2525, in wsgi_app
    response = self.full_dispatch_request()
  File "C:\Users\pc\anaconda3\lib\site-packages\flask\app.py", line 1822, in full_dispatch_request
    rv = self.handle_user_exception(e)
  File "C:\Users\pc\anaconda3\lib\site-packages\flask\app.py", line 1820, in full_dispatch_request
    rv = self.dispatch_request()
  File "C:\Users\pc\anaconda3\lib\site-packages\flask\app.py", line 1796, in dispatch_request
    return self.ensure_sync(self.view_functions[rule.endpoint])(**view_args)
  File "C:\Users\pc\Desktop\enervivo\APIproject\TADD_API\APIproject2.py", line 417, in calculate_pv
    if single_res_for_config[config_name] is not None:
KeyError: 'toiture_surface1'
2023-08-18 19:09:27,029 - APIproject2 - ERROR - Exception on /calculate_pv [POST]
Traceback (most recent call last):
  File "C:\Users\pc\anaconda3\lib\site-packages\flask\app.py", line 2525, in wsgi_app
    response = self.full_dispatch_request()
  File "C:\Users\pc\anaconda3\lib\site-packages\flask\app.py", line 1822, in full_dispatch_request
    rv = self.handle_user_exception(e)
  File "C:\Users\pc\anaconda3\lib\site-packages\flask\app.py", line 1820, in full_dispatch_request
    rv = self.dispatch_request()
  File "C:\Users\pc\anaconda3\lib\site-packages\flask\app.py", line 1796, in dispatch_request
    return self.ensure_sync(self.view_functions[rule.endpoint])(**view_args)
  File "C:\Users\pc\Desktop\enervivo\APIproject\TADD_API\APIproject2.py", line 417, in calculate_pv
    if "surface_azimuth" in config and single_res_for_config[config_name] is not None:
KeyError: 'toiture_surface1'
