2023-08-18 14:34:16,464 - APIproject2 - ERROR - Exception on /calculate_pv [POST]
Traceback (most recent call last):
  File "/home/meshuggah/.local/lib/python3.10/site-packages/flask/app.py", line 2190, in wsgi_app
    response = self.full_dispatch_request()
  File "/home/meshuggah/.local/lib/python3.10/site-packages/flask/app.py", line 1486, in full_dispatch_request
    rv = self.handle_user_exception(e)
  File "/home/meshuggah/.local/lib/python3.10/site-packages/flask/app.py", line 1484, in full_dispatch_request
    rv = self.dispatch_request()
  File "/home/meshuggah/.local/lib/python3.10/site-packages/flask/app.py", line 1469, in dispatch_request
    return self.ensure_sync(self.view_functions[rule.endpoint])(**view_args)
  File "/home/meshuggah/heavy/enervivo/APIproject/TADD_API/APIproject2.py", line 172, in calculate_pv
    configuration = Configuration(**configuration_data)
  File "pydantic/main.py", line 341, in pydantic.main.BaseModel.__init__
pydantic.error_wrappers.ValidationError: 1 validation error for Configuration
long
  field required (type=value_error.missing)
